<?xml version="1.0" encoding="UTF-8"?>
<testsuite name="tests.weeder.WEEDERTests-20210727152523" tests="2" file="tests/weeder.py" time="24.711" timestamp="2021-07-27T15:25:54" failures="0" errors="1" skipped="0">
	<testcase classname="tests.weeder.WEEDERTests" name="test_WHEN_set_voltage_THEN_get_voltage_back_correctly" time="0.452" timestamp="2021-07-27T15:25:54" file="tests\weeder.py" line="42"/>
	<testcase classname="tests.weeder.WEEDERTests" name="test_WHEN_set_ramping_voltage_THEN_get_ramping_voltage_correctly" time="24.259" timestamp="2021-07-27T15:25:53" file="tests\weeder.py" line="44">
		<error type="UnableToConnectToPVException" message="Unable to connect to PV TE:NDW1799:WEEDER_01:RAMPVOLT: Connection timeout (event)"><![CDATA[Traceback (most recent call last):
  File "C:\Instrument\Apps\EPICS\support\weeder\master\system_tests\tests\weeder.py", line 45, in test_WHEN_set_ramping_voltage_THEN_get_ramping_voltage_correctly
    self.ca.assert_setting_setpoint_sets_readback(100, "RAMPVOLT")
  File "C:\Instrument\Apps\EPICS\support\IocTestFramework\master\utils\channel_access.py", line 554, in assert_setting_setpoint_sets_readback
    self.assert_that_pv_is(readback_pv, expected_value, timeout=timeout)
  File "C:\Instrument\Apps\EPICS\support\IocTestFramework\master\utils\channel_access.py", line 269, in assert_that_pv_is
    return self.assert_that_pv_value_causes_func_to_return_true(
  File "C:\Instrument\Apps\EPICS\support\IocTestFramework\master\utils\channel_access.py", line 246, in assert_that_pv_value_causes_func_to_return_true
    err = self._wait_for_pv_lambda(partial(_wrapper, message), timeout)
  File "C:\Instrument\Apps\EPICS\support\IocTestFramework\master\utils\channel_access.py", line 212, in _wait_for_pv_lambda
    return wait_for_lambda()
  File "C:\Instrument\Apps\EPICS\support\IocTestFramework\master\utils\channel_access.py", line 229, in _wrapper
    value = self.get_pv_value(pv)
  File "C:\Instrument\Apps\EPICS\support\IocTestFramework\master\utils\channel_access.py", line 139, in get_pv_value
    return self.ca.get_pv_value(self.create_pv_with_prefix(pv))
  File "C:\Instrument\Apps\Python3\lib\site-packages\genie_python\genie_cachannel_wrapper.py", line 234, in get_pv_value
    chan = CaChannelWrapper.get_chan(name)
  File "C:\Instrument\Apps\Python3\lib\site-packages\genie_python\genie_cachannel_wrapper.py", line 212, in get_chan
    CaChannelWrapper.connect_to_pv(chan)
  File "C:\Instrument\Apps\Python3\lib\site-packages\genie_python\genie_cachannel_wrapper.py", line 333, in connect_to_pv
    raise UnableToConnectToPVException(ca_channel.name(), "Connection timeout (event)")
genie_python.channel_access_exceptions.UnableToConnectToPVException: Unable to connect to PV TE:NDW1799:WEEDER_01:RAMPVOLT: Connection timeout (event)
]]></error>
	</testcase>
</testsuite>
