<?xml version="1.0" encoding="UTF-8"?>
<testsuite name="tests.weeder.WEEDERTests-20210728115057" tests="8" file="tests/weeder.py" time="164.923" timestamp="2021-07-28T11:53:57" failures="7" errors="1" skipped="0">
	<testcase classname="tests.weeder.WEEDERTests" name="test_WHEN_set_default_voltage_THEN_get_default_voltage_correctly" time="20.125" timestamp="2021-07-28T11:51:56" file="tests\weeder.py" line="54">
		<failure type="AssertionError" message="Expected PV, 'TE:NDW1799:WEEDER_01:DEFAULT' to have value '100' (type: 'int').
Final PV value was '0.0' (type: 'float')"><![CDATA[Traceback (most recent call last):
  File "C:\Instrument\Apps\EPICS\support\weeder\master\system_tests\tests\weeder.py", line 55, in test_WHEN_set_default_voltage_THEN_get_default_voltage_correctly
    self.ca.assert_setting_setpoint_sets_readback(100, "DEFAULT")
  File "C:\Instrument\Apps\EPICS\support\IocTestFramework\master\utils\channel_access.py", line 554, in assert_setting_setpoint_sets_readback
    self.assert_that_pv_is(readback_pv, expected_value, timeout=timeout)
  File "C:\Instrument\Apps\EPICS\support\IocTestFramework\master\utils\channel_access.py", line 269, in assert_that_pv_is
    return self.assert_that_pv_value_causes_func_to_return_true(
  File "C:\Instrument\Apps\EPICS\support\IocTestFramework\master\utils\channel_access.py", line 248, in assert_that_pv_value_causes_func_to_return_true
    raise AssertionError(err)
AssertionError: Expected PV, 'TE:NDW1799:WEEDER_01:DEFAULT' to have value '100' (type: 'int').
Final PV value was '0.0' (type: 'float')
]]></failure>
	</testcase>
	<testcase classname="tests.weeder.WEEDERTests" name="test_WHEN_set_padding_THEN_get_padding_correctly" time="20.156" timestamp="2021-07-28T11:52:16" file="tests\weeder.py" line="48">
		<failure type="AssertionError" message="Expected PV, 'TE:NDW1799:WEEDER_01:PADDING' to have value '100' (type: 'int').
Final PV value was '0.0' (type: 'float')"><![CDATA[Traceback (most recent call last):
  File "C:\Instrument\Apps\EPICS\support\weeder\master\system_tests\tests\weeder.py", line 49, in test_WHEN_set_padding_THEN_get_padding_correctly
    self.ca.assert_setting_setpoint_sets_readback(100, "PADDING")
  File "C:\Instrument\Apps\EPICS\support\IocTestFramework\master\utils\channel_access.py", line 554, in assert_setting_setpoint_sets_readback
    self.assert_that_pv_is(readback_pv, expected_value, timeout=timeout)
  File "C:\Instrument\Apps\EPICS\support\IocTestFramework\master\utils\channel_access.py", line 269, in assert_that_pv_is
    return self.assert_that_pv_value_causes_func_to_return_true(
  File "C:\Instrument\Apps\EPICS\support\IocTestFramework\master\utils\channel_access.py", line 248, in assert_that_pv_value_causes_func_to_return_true
    raise AssertionError(err)
AssertionError: Expected PV, 'TE:NDW1799:WEEDER_01:PADDING' to have value '100' (type: 'int').
Final PV value was '0.0' (type: 'float')
]]></failure>
	</testcase>
	<testcase classname="tests.weeder.WEEDERTests" name="test_WHEN_set_ramp_rate_THEN_get_ramp_rate_correctly" time="20.143" timestamp="2021-07-28T11:52:36" file="tests\weeder.py" line="50">
		<failure type="AssertionError" message="Expected PV, 'TE:NDW1799:WEEDER_01:RAMPRATE' to have value '100' (type: 'int').
Final PV value was '0.0' (type: 'float')"><![CDATA[Traceback (most recent call last):
  File "C:\Instrument\Apps\EPICS\support\weeder\master\system_tests\tests\weeder.py", line 51, in test_WHEN_set_ramp_rate_THEN_get_ramp_rate_correctly
    self.ca.assert_setting_setpoint_sets_readback(100, "RAMPRATE")
  File "C:\Instrument\Apps\EPICS\support\IocTestFramework\master\utils\channel_access.py", line 554, in assert_setting_setpoint_sets_readback
    self.assert_that_pv_is(readback_pv, expected_value, timeout=timeout)
  File "C:\Instrument\Apps\EPICS\support\IocTestFramework\master\utils\channel_access.py", line 269, in assert_that_pv_is
    return self.assert_that_pv_value_causes_func_to_return_true(
  File "C:\Instrument\Apps\EPICS\support\IocTestFramework\master\utils\channel_access.py", line 248, in assert_that_pv_value_causes_func_to_return_true
    raise AssertionError(err)
AssertionError: Expected PV, 'TE:NDW1799:WEEDER_01:RAMPRATE' to have value '100' (type: 'int').
Final PV value was '0.0' (type: 'float')
]]></failure>
	</testcase>
	<testcase classname="tests.weeder.WEEDERTests" name="test_WHEN_set_scurve_ramping_voltage_THEN_get_ramping_voltage_correctly" time="20.158" timestamp="2021-07-28T11:52:56" file="tests\weeder.py" line="46">
		<failure type="AssertionError" message="Expected PV, 'TE:NDW1799:WEEDER_01:RAMPVOLT_S' to have value '100' (type: 'int').
Final PV value was '0.0' (type: 'float')"><![CDATA[Traceback (most recent call last):
  File "C:\Instrument\Apps\EPICS\support\weeder\master\system_tests\tests\weeder.py", line 47, in test_WHEN_set_scurve_ramping_voltage_THEN_get_ramping_voltage_correctly
    self.ca.assert_setting_setpoint_sets_readback(100, "RAMPVOLT_S")
  File "C:\Instrument\Apps\EPICS\support\IocTestFramework\master\utils\channel_access.py", line 554, in assert_setting_setpoint_sets_readback
    self.assert_that_pv_is(readback_pv, expected_value, timeout=timeout)
  File "C:\Instrument\Apps\EPICS\support\IocTestFramework\master\utils\channel_access.py", line 269, in assert_that_pv_is
    return self.assert_that_pv_value_causes_func_to_return_true(
  File "C:\Instrument\Apps\EPICS\support\IocTestFramework\master\utils\channel_access.py", line 248, in assert_that_pv_value_causes_func_to_return_true
    raise AssertionError(err)
AssertionError: Expected PV, 'TE:NDW1799:WEEDER_01:RAMPVOLT_S' to have value '100' (type: 'int').
Final PV value was '0.0' (type: 'float')
]]></failure>
	</testcase>
	<testcase classname="tests.weeder.WEEDERTests" name="test_WHEN_set_trapezoid_ramping_voltage_THEN_get_ramping_voltage_correctly" time="20.126" timestamp="2021-07-28T11:53:16" file="tests\weeder.py" line="44">
		<failure type="AssertionError" message="Expected PV, 'TE:NDW1799:WEEDER_01:RAMPVOLT_T' to have value '100' (type: 'int').
Final PV value was '0.0' (type: 'float')"><![CDATA[Traceback (most recent call last):
  File "C:\Instrument\Apps\EPICS\support\weeder\master\system_tests\tests\weeder.py", line 45, in test_WHEN_set_trapezoid_ramping_voltage_THEN_get_ramping_voltage_correctly
    self.ca.assert_setting_setpoint_sets_readback(100, "RAMPVOLT_T")
  File "C:\Instrument\Apps\EPICS\support\IocTestFramework\master\utils\channel_access.py", line 554, in assert_setting_setpoint_sets_readback
    self.assert_that_pv_is(readback_pv, expected_value, timeout=timeout)
  File "C:\Instrument\Apps\EPICS\support\IocTestFramework\master\utils\channel_access.py", line 269, in assert_that_pv_is
    return self.assert_that_pv_value_causes_func_to_return_true(
  File "C:\Instrument\Apps\EPICS\support\IocTestFramework\master\utils\channel_access.py", line 248, in assert_that_pv_value_causes_func_to_return_true
    raise AssertionError(err)
AssertionError: Expected PV, 'TE:NDW1799:WEEDER_01:RAMPVOLT_T' to have value '100' (type: 'int').
Final PV value was '0.0' (type: 'float')
]]></failure>
	</testcase>
	<testcase classname="tests.weeder.WEEDERTests" name="test_WHEN_set_voltage_THEN_get_voltage_back_correctly" time="20.136" timestamp="2021-07-28T11:53:37" file="tests\weeder.py" line="42">
		<failure type="AssertionError" message="Expected PV, 'TE:NDW1799:WEEDER_01:VOLT' to have value '100' (type: 'int').
Final PV value was '0.0' (type: 'float')"><![CDATA[Traceback (most recent call last):
  File "C:\Instrument\Apps\EPICS\support\weeder\master\system_tests\tests\weeder.py", line 43, in test_WHEN_set_voltage_THEN_get_voltage_back_correctly
    self.ca.assert_setting_setpoint_sets_readback(100, "VOLT")
  File "C:\Instrument\Apps\EPICS\support\IocTestFramework\master\utils\channel_access.py", line 554, in assert_setting_setpoint_sets_readback
    self.assert_that_pv_is(readback_pv, expected_value, timeout=timeout)
  File "C:\Instrument\Apps\EPICS\support\IocTestFramework\master\utils\channel_access.py", line 269, in assert_that_pv_is
    return self.assert_that_pv_value_causes_func_to_return_true(
  File "C:\Instrument\Apps\EPICS\support\IocTestFramework\master\utils\channel_access.py", line 248, in assert_that_pv_value_causes_func_to_return_true
    raise AssertionError(err)
AssertionError: Expected PV, 'TE:NDW1799:WEEDER_01:VOLT' to have value '100' (type: 'int').
Final PV value was '0.0' (type: 'float')
]]></failure>
	</testcase>
	<testcase classname="tests.weeder.WEEDERTests" name="test_WHEN_set_wait_THEN_get_wait_correctly" time="20.148" timestamp="2021-07-28T11:53:57" file="tests\weeder.py" line="52">
		<failure type="AssertionError" message="Expected PV, 'TE:NDW1799:WEEDER_01:WAIT' to have value '100' (type: 'int').
Final PV value was '0.0' (type: 'float')"><![CDATA[Traceback (most recent call last):
  File "C:\Instrument\Apps\EPICS\support\weeder\master\system_tests\tests\weeder.py", line 53, in test_WHEN_set_wait_THEN_get_wait_correctly
    self.ca.assert_setting_setpoint_sets_readback(100, "WAIT")
  File "C:\Instrument\Apps\EPICS\support\IocTestFramework\master\utils\channel_access.py", line 554, in assert_setting_setpoint_sets_readback
    self.assert_that_pv_is(readback_pv, expected_value, timeout=timeout)
  File "C:\Instrument\Apps\EPICS\support\IocTestFramework\master\utils\channel_access.py", line 269, in assert_that_pv_is
    return self.assert_that_pv_value_causes_func_to_return_true(
  File "C:\Instrument\Apps\EPICS\support\IocTestFramework\master\utils\channel_access.py", line 248, in assert_that_pv_value_causes_func_to_return_true
    raise AssertionError(err)
AssertionError: Expected PV, 'TE:NDW1799:WEEDER_01:WAIT' to have value '100' (type: 'int').
Final PV value was '0.0' (type: 'float')
]]></failure>
	</testcase>
	<testcase classname="tests.weeder.WEEDERTests" name="test_WHEN_set_calibrate_THEN_get_calibrate_correctly" time="23.931" timestamp="2021-07-28T11:51:36" file="tests\weeder.py" line="56">
		<error type="UnableToConnectToPVException" message="Unable to connect to PV TE:NDW1799:WEEDER_01:-100: Connection timeout (event)"><![CDATA[Traceback (most recent call last):
  File "C:\Instrument\Apps\EPICS\support\weeder\master\system_tests\tests\weeder.py", line 57, in test_WHEN_set_calibrate_THEN_get_calibrate_correctly
    self.ca.assert_setting_setpoint_sets_readback(100, -100, "CALIBRATE")
  File "C:\Instrument\Apps\EPICS\support\IocTestFramework\master\utils\channel_access.py", line 554, in assert_setting_setpoint_sets_readback
    self.assert_that_pv_is(readback_pv, expected_value, timeout=timeout)
  File "C:\Instrument\Apps\EPICS\support\IocTestFramework\master\utils\channel_access.py", line 269, in assert_that_pv_is
    return self.assert_that_pv_value_causes_func_to_return_true(
  File "C:\Instrument\Apps\EPICS\support\IocTestFramework\master\utils\channel_access.py", line 246, in assert_that_pv_value_causes_func_to_return_true
    err = self._wait_for_pv_lambda(partial(_wrapper, message), timeout)
  File "C:\Instrument\Apps\EPICS\support\IocTestFramework\master\utils\channel_access.py", line 212, in _wait_for_pv_lambda
    return wait_for_lambda()
  File "C:\Instrument\Apps\EPICS\support\IocTestFramework\master\utils\channel_access.py", line 229, in _wrapper
    value = self.get_pv_value(pv)
  File "C:\Instrument\Apps\EPICS\support\IocTestFramework\master\utils\channel_access.py", line 139, in get_pv_value
    return self.ca.get_pv_value(self.create_pv_with_prefix(pv))
  File "C:\Instrument\Apps\Python3\lib\site-packages\genie_python\genie_cachannel_wrapper.py", line 234, in get_pv_value
    chan = CaChannelWrapper.get_chan(name)
  File "C:\Instrument\Apps\Python3\lib\site-packages\genie_python\genie_cachannel_wrapper.py", line 212, in get_chan
    CaChannelWrapper.connect_to_pv(chan)
  File "C:\Instrument\Apps\Python3\lib\site-packages\genie_python\genie_cachannel_wrapper.py", line 333, in connect_to_pv
    raise UnableToConnectToPVException(ca_channel.name(), "Connection timeout (event)")
genie_python.channel_access_exceptions.UnableToConnectToPVException: Unable to connect to PV TE:NDW1799:WEEDER_01:-100: Connection timeout (event)
]]></error>
	</testcase>
</testsuite>
