<?xml version="1.0" encoding="UTF-8"?>
<testsuite name="tests.weeder.WEEDERTests-20210728110313" tests="5" file="tests/weeder.py" time="100.382" timestamp="2021-07-28T11:05:01" failures="5" errors="0" skipped="0">
	<testcase classname="tests.weeder.WEEDERTests" name="test_WHEN_set_padding_THEN_get_padding_correctly" time="20.080" timestamp="2021-07-28T11:03:40" file="tests\weeder.py" line="48">
		<failure type="AssertionError" message="Expected PV, 'TE:NDW1799:WEEDER_01:PADDING' to have value '100' (type: 'int').
Final PV value was '0.0' (type: 'float')"><![CDATA[Traceback (most recent call last):
  File "C:\Instrument\Apps\EPICS\support\weeder\master\system_tests\tests\weeder.py", line 49, in test_WHEN_set_padding_THEN_get_padding_correctly
    self.ca.assert_setting_setpoint_sets_readback(100, "PADDING")
  File "C:\Instrument\Apps\EPICS\support\IocTestFramework\master\utils\channel_access.py", line 554, in assert_setting_setpoint_sets_readback
    self.assert_that_pv_is(readback_pv, expected_value, timeout=timeout)
  File "C:\Instrument\Apps\EPICS\support\IocTestFramework\master\utils\channel_access.py", line 269, in assert_that_pv_is
    return self.assert_that_pv_value_causes_func_to_return_true(
  File "C:\Instrument\Apps\EPICS\support\IocTestFramework\master\utils\channel_access.py", line 248, in assert_that_pv_value_causes_func_to_return_true
    raise AssertionError(err)
AssertionError: Expected PV, 'TE:NDW1799:WEEDER_01:PADDING' to have value '100' (type: 'int').
Final PV value was '0.0' (type: 'float')
]]></failure>
	</testcase>
	<testcase classname="tests.weeder.WEEDERTests" name="test_WHEN_set_ramp_rate_THEN_get_ramp_rate_correctly" time="20.060" timestamp="2021-07-28T11:04:00" file="tests\weeder.py" line="50">
		<failure type="AssertionError" message="Expected PV, 'TE:NDW1799:WEEDER_01:RAMPRATE' to have value '100' (type: 'int').
Final PV value was '0.0' (type: 'float')"><![CDATA[Traceback (most recent call last):
  File "C:\Instrument\Apps\EPICS\support\weeder\master\system_tests\tests\weeder.py", line 51, in test_WHEN_set_ramp_rate_THEN_get_ramp_rate_correctly
    self.ca.assert_setting_setpoint_sets_readback(100, "RAMPRATE")
  File "C:\Instrument\Apps\EPICS\support\IocTestFramework\master\utils\channel_access.py", line 554, in assert_setting_setpoint_sets_readback
    self.assert_that_pv_is(readback_pv, expected_value, timeout=timeout)
  File "C:\Instrument\Apps\EPICS\support\IocTestFramework\master\utils\channel_access.py", line 269, in assert_that_pv_is
    return self.assert_that_pv_value_causes_func_to_return_true(
  File "C:\Instrument\Apps\EPICS\support\IocTestFramework\master\utils\channel_access.py", line 248, in assert_that_pv_value_causes_func_to_return_true
    raise AssertionError(err)
AssertionError: Expected PV, 'TE:NDW1799:WEEDER_01:RAMPRATE' to have value '100' (type: 'int').
Final PV value was '0.0' (type: 'float')
]]></failure>
	</testcase>
	<testcase classname="tests.weeder.WEEDERTests" name="test_WHEN_set_scurve_ramping_voltage_THEN_get_ramping_voltage_correctly" time="20.060" timestamp="2021-07-28T11:04:20" file="tests\weeder.py" line="46">
		<failure type="AssertionError" message="Expected PV, 'TE:NDW1799:WEEDER_01:RAMPVOLT_S' to have value '100' (type: 'int').
Final PV value was '0.0' (type: 'float')"><![CDATA[Traceback (most recent call last):
  File "C:\Instrument\Apps\EPICS\support\weeder\master\system_tests\tests\weeder.py", line 47, in test_WHEN_set_scurve_ramping_voltage_THEN_get_ramping_voltage_correctly
    self.ca.assert_setting_setpoint_sets_readback(100, "RAMPVOLT_S")
  File "C:\Instrument\Apps\EPICS\support\IocTestFramework\master\utils\channel_access.py", line 554, in assert_setting_setpoint_sets_readback
    self.assert_that_pv_is(readback_pv, expected_value, timeout=timeout)
  File "C:\Instrument\Apps\EPICS\support\IocTestFramework\master\utils\channel_access.py", line 269, in assert_that_pv_is
    return self.assert_that_pv_value_causes_func_to_return_true(
  File "C:\Instrument\Apps\EPICS\support\IocTestFramework\master\utils\channel_access.py", line 248, in assert_that_pv_value_causes_func_to_return_true
    raise AssertionError(err)
AssertionError: Expected PV, 'TE:NDW1799:WEEDER_01:RAMPVOLT_S' to have value '100' (type: 'int').
Final PV value was '0.0' (type: 'float')
]]></failure>
	</testcase>
	<testcase classname="tests.weeder.WEEDERTests" name="test_WHEN_set_trapezoid_ramping_voltage_THEN_get_ramping_voltage_correctly" time="20.096" timestamp="2021-07-28T11:04:41" file="tests\weeder.py" line="44">
		<failure type="AssertionError" message="Expected PV, 'TE:NDW1799:WEEDER_01:RAMPVOLT_T' to have value '100' (type: 'int').
Final PV value was '0.0' (type: 'float')"><![CDATA[Traceback (most recent call last):
  File "C:\Instrument\Apps\EPICS\support\weeder\master\system_tests\tests\weeder.py", line 45, in test_WHEN_set_trapezoid_ramping_voltage_THEN_get_ramping_voltage_correctly
    self.ca.assert_setting_setpoint_sets_readback(100, "RAMPVOLT_T")
  File "C:\Instrument\Apps\EPICS\support\IocTestFramework\master\utils\channel_access.py", line 554, in assert_setting_setpoint_sets_readback
    self.assert_that_pv_is(readback_pv, expected_value, timeout=timeout)
  File "C:\Instrument\Apps\EPICS\support\IocTestFramework\master\utils\channel_access.py", line 269, in assert_that_pv_is
    return self.assert_that_pv_value_causes_func_to_return_true(
  File "C:\Instrument\Apps\EPICS\support\IocTestFramework\master\utils\channel_access.py", line 248, in assert_that_pv_value_causes_func_to_return_true
    raise AssertionError(err)
AssertionError: Expected PV, 'TE:NDW1799:WEEDER_01:RAMPVOLT_T' to have value '100' (type: 'int').
Final PV value was '0.0' (type: 'float')
]]></failure>
	</testcase>
	<testcase classname="tests.weeder.WEEDERTests" name="test_WHEN_set_voltage_THEN_get_voltage_back_correctly" time="20.087" timestamp="2021-07-28T11:05:01" file="tests\weeder.py" line="42">
		<failure type="AssertionError" message="Expected PV, 'TE:NDW1799:WEEDER_01:VOLT' to have value '100' (type: 'int').
Final PV value was '0.0' (type: 'float')"><![CDATA[Traceback (most recent call last):
  File "C:\Instrument\Apps\EPICS\support\weeder\master\system_tests\tests\weeder.py", line 43, in test_WHEN_set_voltage_THEN_get_voltage_back_correctly
    self.ca.assert_setting_setpoint_sets_readback(100, "VOLT")
  File "C:\Instrument\Apps\EPICS\support\IocTestFramework\master\utils\channel_access.py", line 554, in assert_setting_setpoint_sets_readback
    self.assert_that_pv_is(readback_pv, expected_value, timeout=timeout)
  File "C:\Instrument\Apps\EPICS\support\IocTestFramework\master\utils\channel_access.py", line 269, in assert_that_pv_is
    return self.assert_that_pv_value_causes_func_to_return_true(
  File "C:\Instrument\Apps\EPICS\support\IocTestFramework\master\utils\channel_access.py", line 248, in assert_that_pv_value_causes_func_to_return_true
    raise AssertionError(err)
AssertionError: Expected PV, 'TE:NDW1799:WEEDER_01:VOLT' to have value '100' (type: 'int').
Final PV value was '0.0' (type: 'float')
]]></failure>
	</testcase>
</testsuite>
