<?xml version="1.0" encoding="UTF-8"?>
<testsuite name="tests.weeder.WEEDERTests-20210726161944" tests="1" file="tests/weeder.py" time="0.002" timestamp="2021-07-26T16:19:57" failures="0" errors="1" skipped="0">
	<testcase classname="tests.weeder.WEEDERTests" name="test_WHEN_set_voltage_THEN_get_voltage_back_correctly" time="0.002" timestamp="2021-07-26T16:19:57" file="tests\weeder.py" line="42">
		<error type="AttributeError" message="'tuple' object has no attribute 'assert_setting_setpoint_sets_readback'"><![CDATA[Traceback (most recent call last):
  File "C:\Instrument\Apps\EPICS\support\weeder\master\system_tests\tests\weeder.py", line 43, in test_WHEN_set_voltage_THEN_get_voltage_back_correctly
    self.ca.assert_setting_setpoint_sets_readback(100, "VOLT")
AttributeError: 'tuple' object has no attribute 'assert_setting_setpoint_sets_readback'
]]></error>
	</testcase>
</testsuite>
